<?xml version="1.0" ?>
<robot name="final_project" xmlns:xacro="http://www.ros.org/wiki/xacro">

<xacro:include filename="$(find final_project_description)/urdf/materials.xacro" />
<xacro:include filename="$(find final_project_description)/urdf/final_project.trans" />
<xacro:include filename="$(find final_project_description)/urdf/final_project.gazebo" />
<link name="base_link">
  <inertial>
    <origin xyz="-0.0038261578149996634 0.044429126297514804 -0.014040038900409087" rpy="0 0 0"/>
    <mass value="0.48964662836381656"/>
    <inertia ixx="0.000748" iyy="0.000997" izz="0.000384" ixy="0.0" iyz="6e-06" ixz="-0.0"/>
  </inertial>
  <visual>
    <origin xyz="0 0 0" rpy="0 0 0"/>
    <geometry>
      <mesh filename="file://$(find final_project_description)/meshes/base_link.stl" scale="0.001 0.001 0.001"/>
    </geometry>
    <material name="silver"/>
  </visual>
  <collision>
    <origin xyz="0 0 0" rpy="0 0 0"/>
    <geometry>
      <mesh filename="file://$(find final_project_description)/meshes/base_link.stl" scale="0.001 0.001 0.001"/>
    </geometry>
  </collision>
</link>

<link name="right_front_wheel_1">
  <inertial>
    <origin xyz="-0.005000157814999649 3.114103060281037e-07 4.006736244871467e-07" rpy="0 0 0"/>
    <mass value="0.026295130510546567"/>
    <inertia ixx="1.2e-05" iyy="6e-06" izz="6e-06" ixy="0.0" iyz="0.0" ixz="-0.0"/>
  </inertial>
  <visual>
    <origin xyz="0.053826 -0.038961 -0.032067" rpy="0 0 0"/>
    <geometry>
      <mesh filename="file://$(find final_project_description)/meshes/right_front_wheel_1.stl" scale="0.001 0.001 0.001"/>
    </geometry>
    <material name="silver"/>
  </visual>
  <collision>
    <origin xyz="0.053826 -0.038961 -0.032067" rpy="0 0 0"/>
    <geometry>
      <mesh filename="file://$(find final_project_description)/meshes/right_front_wheel_1.stl" scale="0.001 0.001 0.001"/>
    </geometry>
  </collision>
</link>

<link name="left_front_wheel_1">
  <inertial>
    <origin xyz="0.004999842185000179 3.1141030598647035e-07 4.0067362440388e-07" rpy="0 0 0"/>
    <mass value="0.026295130510546567"/>
    <inertia ixx="1.2e-05" iyy="6e-06" izz="6e-06" ixy="0.0" iyz="0.0" ixz="-0.0"/>
  </inertial>
  <visual>
    <origin xyz="-0.046174 -0.038961 -0.032067" rpy="0 0 0"/>
    <geometry>
      <mesh filename="file://$(find final_project_description)/meshes/left_front_wheel_1.stl" scale="0.001 0.001 0.001"/>
    </geometry>
    <material name="silver"/>
  </visual>
  <collision>
    <origin xyz="-0.046174 -0.038961 -0.032067" rpy="0 0 0"/>
    <geometry>
      <mesh filename="file://$(find final_project_description)/meshes/left_front_wheel_1.stl" scale="0.001 0.001 0.001"/>
    </geometry>
  </collision>
</link>

<link name="right_back_wheel_1">
  <inertial>
    <origin xyz="-0.005000157814999538 3.114103059378981e-07 4.006736245079634e-07" rpy="0 0 0"/>
    <mass value="0.02629513051054656"/>
    <inertia ixx="1.2e-05" iyy="6e-06" izz="6e-06" ixy="0.0" iyz="0.0" ixz="-0.0"/>
  </inertial>
  <visual>
    <origin xyz="0.053826 -0.038961 0.057933" rpy="0 0 0"/>
    <geometry>
      <mesh filename="file://$(find final_project_description)/meshes/right_back_wheel_1.stl" scale="0.001 0.001 0.001"/>
    </geometry>
    <material name="silver"/>
  </visual>
  <collision>
    <origin xyz="0.053826 -0.038961 0.057933" rpy="0 0 0"/>
    <geometry>
      <mesh filename="file://$(find final_project_description)/meshes/right_back_wheel_1.stl" scale="0.001 0.001 0.001"/>
    </geometry>
  </collision>
</link>

<link name="left_back_wheel_1">
  <inertial>
    <origin xyz="0.004999842185000297 3.114103059032036e-07 4.0067362440388e-07" rpy="0 0 0"/>
    <mass value="0.02629513051054656"/>
    <inertia ixx="1.2e-05" iyy="6e-06" izz="6e-06" ixy="0.0" iyz="0.0" ixz="-0.0"/>
  </inertial>
  <visual>
    <origin xyz="-0.046174 -0.038961 0.057933" rpy="0 0 0"/>
    <geometry>
      <mesh filename="file://$(find final_project_description)/meshes/left_back_wheel_1.stl" scale="0.001 0.001 0.001"/>
    </geometry>
    <material name="silver"/>
  </visual>
  <collision>
    <origin xyz="-0.046174 -0.038961 0.057933" rpy="0 0 0"/>
    <geometry>
      <mesh filename="file://$(find final_project_description)/meshes/left_back_wheel_1.stl" scale="0.001 0.001 0.001"/>
    </geometry>
  </collision>
</link>

<link name="lidar_1">
  <inertial>
    <origin xyz="-1.5781526106805124e-07 0.015000311410305958 4.006736244871467e-07" rpy="0 0 0"/>
    <mass value="0.002497566159603939"/>
    <inertia ixx="0.0" iyy="0.0" izz="0.0" ixy="-0.0" iyz="0.0" ixz="-0.0"/>
  </inertial>
  <visual>
    <origin xyz="0.003826 -0.068961 -0.032067" rpy="0 0 0"/>
    <geometry>
      <mesh filename="file://$(find final_project_description)/meshes/lidar_1.stl" scale="0.001 0.001 0.001"/>
    </geometry>
    <material name="silver"/>
  </visual>
  <collision>
    <origin xyz="0.003826 -0.068961 -0.032067" rpy="0 0 0"/>
    <geometry>
      <mesh filename="file://$(find final_project_description)/meshes/lidar_1.stl" scale="0.001 0.001 0.001"/>
    </geometry>
  </collision>
</link>

<link name="camera_1">
  <inertial>
    <origin xyz="-1.5781499976058252e-07 3.114103060350426e-07 0.002500400673624441" rpy="0 0 0"/>
    <mass value="0.0016650441064025904"/>
    <inertia ixx="0.0" iyy="0.0" izz="0.0" ixy="0.0" iyz="0.0" ixz="-0.0"/>
  </inertial>
  <visual>
    <origin xyz="0.003826 -0.043961 -0.052067" rpy="0 0 0"/>
    <geometry>
      <mesh filename="file://$(find final_project_description)/meshes/camera_1.stl" scale="0.001 0.001 0.001"/>
    </geometry>
    <material name="silver"/>
  </visual>
  <collision>
    <origin xyz="0.003826 -0.043961 -0.052067" rpy="0 0 0"/>
    <geometry>
      <mesh filename="file://$(find final_project_description)/meshes/camera_1.stl" scale="0.001 0.001 0.001"/>
    </geometry>
  </collision>
</link>

<link name="candy_1">
  <inertial>
    <origin xyz="-1.5781499960879422e-07 0.005000311410306019 4.006736244802078e-07" rpy="0 0 0"/>
    <mass value="0.002712844435228289"/>
    <inertia ixx="0.0" iyy="0.0" izz="0.0" ixy="0.0" iyz="0.0" ixz="-0.0"/>
  </inertial>
  <visual>
    <origin xyz="0.003826 -0.063961 0.052933" rpy="0 0 0"/>
    <geometry>
      <mesh filename="file://$(find final_project_description)/meshes/candy_1.stl" scale="0.001 0.001 0.001"/>
    </geometry>
    <material name="silver"/>
  </visual>
  <collision>
    <origin xyz="0.003826 -0.063961 0.052933" rpy="0 0 0"/>
    <geometry>
      <mesh filename="file://$(find final_project_description)/meshes/candy_1.stl" scale="0.001 0.001 0.001"/>
    </geometry>
  </collision>
</link>

<joint name="Revolute 7" type="continuous">
  <origin xyz="-0.053826 0.038961 0.032067" rpy="0 0 0"/>
  <parent link="base_link"/>
  <child link="right_front_wheel_1"/>
  <axis xyz="-1.0 0.0 0.0"/>
</joint>

<joint name="Revolute 8" type="continuous">
  <origin xyz="0.046174 0.038961 0.032067" rpy="0 0 0"/>
  <parent link="base_link"/>
  <child link="left_front_wheel_1"/>
  <axis xyz="1.0 -0.0 -0.0"/>
</joint>

<joint name="Revolute 9" type="continuous">
  <origin xyz="-0.053826 0.038961 -0.057933" rpy="0 0 0"/>
  <parent link="base_link"/>
  <child link="right_back_wheel_1"/>
  <axis xyz="-1.0 0.0 0.0"/>
</joint>

<joint name="Revolute 10" type="continuous">
  <origin xyz="0.046174 0.038961 -0.057933" rpy="0 0 0"/>
  <parent link="base_link"/>
  <child link="left_back_wheel_1"/>
  <axis xyz="1.0 -0.0 -0.0"/>
</joint>

<joint name="Rigid 12" type="fixed">
  <origin xyz="-0.003826 0.068961 0.032067" rpy="0 0 0"/>
  <parent link="base_link"/>
  <child link="lidar_1"/>
</joint>

<joint name="Rigid 13" type="fixed">
  <origin xyz="-0.003826 0.043961 0.052067" rpy="0 0 0"/>
  <parent link="base_link"/>
  <child link="camera_1"/>
</joint>

<joint name="Rigid 14" type="fixed">
  <origin xyz="-0.003826 0.063961 -0.052933" rpy="0 0 0"/>
  <parent link="base_link"/>
  <child link="candy_1"/>
</joint>

</robot>
